# 47장. 에러처리

## 목차

- [47.1 에러 처리의 필요성](#471-에러-처리의-필요성)
- [47.2 try catch finally문](#472-try-catch-finally문)
- [47.3 Error 객체](#473-error-객체)
- [47.4 throw 문](#474-throw-문)
- [47.5 에러의 전파](#475-에러의-전파)

---

## 47.1 에러 처리의 필요성

`try` `catch`문으로 에러에 대응하거나, `if` 문을 통해 메서드의 반환값을 확인하거나, 단축 평가(||, &&) 또는 옵셔널 체이닝을 사용하는 등으로 프로그램이 강제 종료되지 않도록 에러 처리는 필요하다.

## 47.2 try catch finally문

에러 처리의 구현은 크게 두 가지가 있다.

- `if` 문이나 단축 평가, 옵셔널 체이닝을 통해 확인해서 처리
- 에러 처리 코드를 미리 등록해 두고, 에러가 발생하면 에러 처리 코드로 점프

`try` `catch` `finally`문은 두 번째 방법이다.

`try`에서 에러가 발생하면 `catch`문의 `err` 변수에 전달되고, `catch`가 실행된다. `finally`는 에러와 관계 없이 반드시 한 번 실행된다.

```jsx
console.log('[Start]');

try {
  foo();
} catch (error) {
  console.error('[에러 발생]', error);
  // [에러 발생] ReferenceError: foo is not defined
}

// 발생한 에러에 적절한 대응을 하면 프로그램이 강제 종료되지 않는다.
console.log('[End]');
```

## 47.3 Error 객체

Error 생성자 함수는 에러 메시지를 인수로 하여 에러 객체를 생성한다.

Error 객체는 `message` 프로퍼티와 `stack` 프로퍼티를 갖는다.

- `message`
    - 생성자 함수에 인수로 전달한 에러 메시지
- `stack`
    - 에러를 발생시킨 콜스택의 호출 정보를 나타내는 문자열

자바스크립트는 7개의 에러 객체를 생성할 수 있는 Error 생성자 함수를 제공한다. 에러 객체의 프로토타입은 모두 `Error.prototype`을 상속받는다.

| 생성자 함수 | 인스턴스 |
| --- | --- |
| `Error` | 일반적 에러 객체 |
| `SyntaxError` | 자바스크립트 문법에 맞지 않는 문을 해석할 때 발생하는 에러 객체 |
| `ReferenceError` | 참조할 수 없는 식별자를 참조했을 때 발생하는 에러 객체 |
| `TypeError` | 피연산자 또는 인수의 데이터타입이 유효하지 않을 때 발생하는 에러 객체 |
| `RangeError` | 숫자값의 허용 범위를 벗어났을 때 발생하는 에러 객체 |
| `URIError` | encodeURI 또는 decodeURI 함수에 부적절한 인수를 전달했을 때 발생하는 에러 객체 |
| `EvalError` | eval 함수에서 발생하는 에러 객체 |

```jsx
1 @ 1;    // SyntaxError: Invalid or unexpected token
foo();    // ReferenceError: foo is not defined
null.foo; // TypeError: Cannot read property 'foo' of null
new Array(-1); // RangeError: Invalid array length
decodeURIComponent('%'); // URIError: URI malformed
```

## 47.4 throw 문

에러 객체 생성과 에러 발생은 의미가 다르다.

에러를 발생시키려면, try 코드 블록에서 `throw` 문으로 에러 객체를 던져야 한다.

## 47.5 에러의 전파

에러는 호출자 방향으로 전파된다.

즉, 콜 스택의 아래 방향(실행 중인 실행 컨텍스트가 푸시되기 직전에 푸시된 실행 컨텍스트 방향)으로 전파된다.

```jsx
const foo = () => {
  throw Error('foo에서 발생한 에러'); // ④
};

const bar = () => {
  foo(); // ③
};

const baz = () => {
  bar(); // ②
};

try {
  baz(); // ①
} catch (err) {
  console.error(err);
}
```

콜 스택은 다음과 같은 모양이다.

- foo 실행 컨텍스트 → 에러 발생!
- bar 실행 컨텍스트
- baz 실행 컨텍스트
- 전역 실행 컨텍스트

따라서 `bar` → `baz` → `전역`으로 에러는 전파되며, 이 때 `throw`된 에러를 어디에서도 캐치하지 않으면 프로그램은 강제 종료된다.

주의할 것은, 비동기 함수인 `setTimeout`이나 프로미스 후속 처리 메서드의 콜백 함수는 **호출자가 없다**는 것이다.

이들은 콜 스택이 비면 이벤트 루프에 의해 콜 스택으로 푸시되어 실행된다.

이 때 콜 스택에 푸시된 콜백 함수의 실행 컨텍스트는 **콜 스택의 가장 하부**에 존재하게 되고, 따라서 에러를 전파할 호출자가 존재하지 않는다.